<sdf version='1.7'>
  <world name='default'>
    <gravity>0 0 -9.8</gravity>
    <model name='ground_plane'>
      <static>1</static>
      <link name='link'>
        <collision name='collision'>
          <geometry>
            <plane>
              <normal>0 0 1</normal>
              <size>100 100</size>
            </plane>
          </geometry>
          <surface>
            <contact>
              <collide_bitmask>65535</collide_bitmask>
              <ode/>
            </contact>
            <friction>
              <ode>
                <mu>100</mu>
                <mu2>50</mu2>
              </ode>
              <torsional>
                <ode/>
              </torsional>
            </friction>
            <bounce/>
          </surface>
          <max_contacts>10</max_contacts>
        </collision>
        <visual name='visual'>
          <cast_shadows>0</cast_shadows>
          <geometry>
            <plane>
              <normal>0 0 1</normal>
              <size>100 100</size>
            </plane>
          </geometry>
          <material>
            <script>
              <uri>file://media/materials/scripts/gazebo.material</uri>
              <name>Gazebo/Grey</name>
            </script>
          </material>
        </visual>
        <self_collide>0</self_collide>
        <enable_wind>0</enable_wind>
        <kinematic>0</kinematic>
      </link>
    </model>
    <light name='sun' type='directional'>
      <cast_shadows>1</cast_shadows>
      <pose>0 0 10 0 -0 0</pose>
      <diffuse>0.8 0.8 0.8 1</diffuse>
      <specular>0.2 0.2 0.2 1</specular>
      <attenuation>
        <range>1000</range>
        <constant>0.9</constant>
        <linear>0.01</linear>
        <quadratic>0.001</quadratic>
      </attenuation>
      <direction>-0.5 0.1 -0.9</direction>
      <spot>
        <inner_angle>0</inner_angle>
        <outer_angle>0</outer_angle>
        <falloff>0</falloff>
      </spot>
    </light>
    <scene>
      <shadows>0</shadows>
      <ambient>0.4 0.4 0.4 1</ambient>
      <background>0.7 0.7 0.7 1</background>
    </scene>
    <model name='conveyor_belt'>
      <model name='conveyorbelt_fixed'>
        <static>1</static>
        <link name='belt_visual'>
          <visual name='visual'>
            <geometry>
              <mesh>
                <scale>1 1 1</scale>
                <uri>/mnt/Storage/Documents/MIT/Books/Robotics-2_Lab/Mini_Project/src/conveyorbelt_gazebo/models/conveyor_belt/meshes/conveyor_belt.dae</uri>
              </mesh>
            </geometry>
          </visual>
          <collision name='collision'>
            <geometry>
              <mesh>
                <scale>1 1 1</scale>
                <uri>/mnt/Storage/Documents/MIT/Books/Robotics-2_Lab/Mini_Project/src/conveyorbelt_gazebo/models/conveyor_belt/meshes/conveyor_belt.dae</uri>
              </mesh>
            </geometry>
            <max_contacts>10</max_contacts>
            <surface>
              <contact>
                <ode/>
              </contact>
              <bounce/>
              <friction>
                <torsional>
                  <ode/>
                </torsional>
                <ode/>
              </friction>
            </surface>
            <origin xyz='0.0 0.0 0' rpy='0.0 0.0 0.0'/>
          </collision>
          <self_collide>0</self_collide>
          <enable_wind>0</enable_wind>
          <kinematic>0</kinematic>
        </link>
      </model>
      <model name='conveyorbelt_moving'>
        <allow_auto_disable>0</allow_auto_disable>
        <static>0</static>
        <pose>0 0 0.741 0 -0 0</pose>
        <link name='belt_moving'>
          <inertial>
            <mass>100</mass>
            <inertia>
              <ixx>0</ixx>
              <ixy>0</ixy>
              <ixz>0</ixz>
              <iyy>0</iyy>
              <iyz>0</iyz>
              <izz>0</izz>
            </inertia>
            <pose>0 0 0 0 -0 0</pose>
          </inertial>
          <collision name='belt_collision'>
            <geometry>
              <box>
                <size>0.425 1.2 1e-05</size>
              </box>
            </geometry>
            <surface>
              <friction>
                <ode>
                  <mu>100</mu>
                  <mu2>100</mu2>
                </ode>
                <torsional>
                  <coefficient>1000</coefficient>
                  <patch_radius>0.1</patch_radius>
                  <ode/>
                </torsional>
              </friction>
              <contact>
                <ode/>
              </contact>
              <bounce/>
            </surface>
            <max_contacts>10</max_contacts>
          </collision>
          <self_collide>0</self_collide>
          <enable_wind>0</enable_wind>
          <kinematic>0</kinematic>
        </link>
      </model>
      <joint name='belt_joint' type='prismatic'>
        <parent>conveyorbelt_fixed::belt_visual</parent>
        <child>conveyorbelt_moving::belt_moving</child>
        <axis>
          <xyz expressed_in='__model__'>0 1 0</xyz>
          <limit>
            <lower>0</lower>
            <upper>0.01</upper>
          </limit>
          <dynamics>
            <spring_reference>0</spring_reference>
            <spring_stiffness>0</spring_stiffness>
          </dynamics>
        </axis>
      </joint>
      <plugin name='ros2_conveyorbelt_plugin' filename='libros2_conveyorbelt_plugin.so'>
        <ros>
          <namespace/>
        </ros>
        <max_velocity>1.0</max_velocity>
        <publish_rate>1000</publish_rate>
      </plugin>
      <pose>0 0 0 0 -0 0</pose>
      <gazebo>
        <plugin filename='libROS2ConveyorBeltPlugin.so' name='ros2_conveyorbelt_plugin'>
          <ros>
            <namespace/>
          </ros>
          <max_velocity>0.2</max_velocity>
          <publish_rate>10</publish_rate>
        </plugin>
      </gazebo>
    </model>
    <magnetic_field>6e-06 2.3e-05 -4.2e-05</magnetic_field>
    <atmosphere type='adiabatic'/>
    <physics type='ode'>
      <max_step_size>0.001</max_step_size>
      <real_time_factor>1</real_time_factor>
      <real_time_update_rate>1000</real_time_update_rate>
    </physics>
    <audio>
      <device>default</device>
    </audio>
    <wind/>
    <spherical_coordinates>
      <surface_model>EARTH_WGS84</surface_model>
      <latitude_deg>0</latitude_deg>
      <longitude_deg>0</longitude_deg>
      <elevation>0</elevation>
      <heading_deg>0</heading_deg>
    </spherical_coordinates>
    <model name='ur5'>
      <joint name='world_to_base' type='fixed'>
        <pose relative_to='__model__'>0 0 0 0 -0 0</pose>
        <parent>world</parent>
        <child>base_link</child>
      </joint>
      <link name='base_link'>
        <pose relative_to='world_to_base'>0 0 0 0 -0 0</pose>
        <inertial>
          <pose>-0.000367 -0.000368 0.016561 0 -0 0</pose>
          <mass>4</mass>
          <inertia>
            <ixx>0.00060258</ixx>
            <ixy>1.7502e-05</ixy>
            <ixz>1.5277e-06</ixz>
            <iyy>0.00060261</iyy>
            <iyz>1.5241e-06</iyz>
            <izz>0.0010709</izz>
          </inertia>
        </inertial>
        <collision name='base_link_collision'>
          <pose>0 0 0 0 -0 0</pose>
          <geometry>
            <mesh>
              <scale>1 1 1</scale>
              <uri>/mnt/Storage/Documents/MIT/Books/Robotics-2_Lab/Mini_Project/src/ur5/meshes/base_link.STL</uri>
            </mesh>
          </geometry>
          <surface>
            <contact>
              <ode/>
            </contact>
            <friction>
              <ode/>
              <torsional>
                <ode/>
              </torsional>
            </friction>
            <bounce/>
          </surface>
          <max_contacts>10</max_contacts>
        </collision>
        <visual name='base_link_visual'>
          <pose>0 0 0 0 -0 0</pose>
          <geometry>
            <mesh>
              <scale>1 1 1</scale>
              <uri>/mnt/Storage/Documents/MIT/Books/Robotics-2_Lab/Mini_Project/src/ur5/meshes/base_link.STL</uri>
            </mesh>
          </geometry>
          <material>
            <script>
              <name>Gazebo/Yellow</name>
              <uri>file://media/materials/scripts/gazebo.material</uri>
            </script>
          </material>
        </visual>
        <self_collide>0</self_collide>
        <enable_wind>0</enable_wind>
        <kinematic>0</kinematic>
      </link>
      <joint name='shoulder_pan_joint' type='revolute'>
        <pose relative_to='base_link'>0 0 0.009992 -1.57079 1.57079 3.14159</pose>
        <parent>base_link</parent>
        <child>shoulder_link</child>
        <axis>
          <xyz>1 0 0</xyz>
          <limit>
            <lower>-6.2832</lower>
            <upper>6.2832</upper>
            <effort>300</effort>
            <velocity>3</velocity>
          </limit>
          <dynamics>
            <damping>10</damping>
            <friction>1</friction>
            <spring_reference>0</spring_reference>
            <spring_stiffness>0</spring_stiffness>
          </dynamics>
        </axis>
      </joint>
      <link name='shoulder_link'>
        <pose relative_to='shoulder_pan_joint'>0 0 0 0 -0 0</pose>
        <inertial>
          <pose>-0.078966 0.016439 -6e-06 0 -0 0</pose>
          <mass>3.7</mass>
          <inertia>
            <ixx>0.0028298</ixx>
            <ixy>0.00031932</ixy>
            <ixz>-1.3132e-07</ixz>
            <iyy>0.002538</iyy>
            <iyz>4.4907e-07</iyz>
            <izz>0.0026207</izz>
          </inertia>
        </inertial>
        <collision name='shoulder_link_collision'>
          <pose>0 0 0 0 -0 0</pose>
          <geometry>
            <mesh>
              <scale>1 1 1</scale>
              <uri>/mnt/Storage/Documents/MIT/Books/Robotics-2_Lab/Mini_Project/src/ur5/meshes/shoulder_link.STL</uri>
            </mesh>
          </geometry>
          <surface>
            <contact>
              <ode/>
            </contact>
            <friction>
              <ode/>
              <torsional>
                <ode/>
              </torsional>
            </friction>
            <bounce/>
          </surface>
          <max_contacts>10</max_contacts>
        </collision>
        <visual name='shoulder_link_visual'>
          <pose>0 0 0 0 -0 0</pose>
          <geometry>
            <mesh>
              <scale>1 1 1</scale>
              <uri>/mnt/Storage/Documents/MIT/Books/Robotics-2_Lab/Mini_Project/src/ur5/meshes/shoulder_link.STL</uri>
            </mesh>
          </geometry>
          <material>
            <script>
              <name>Gazebo/Yellow</name>
              <uri>file://media/materials/scripts/gazebo.material</uri>
            </script>
          </material>
        </visual>
        <self_collide>1</self_collide>
        <enable_wind>0</enable_wind>
        <kinematic>0</kinematic>
      </link>
      <joint name='shoulder_lift_joint' type='revolute'>
        <pose relative_to='shoulder_link'>-0.080008 0.053821 0 0 -0 0</pose>
        <parent>shoulder_link</parent>
        <child>upper_arm_link</child>
        <axis>
          <xyz>0 -1 0</xyz>
          <limit>
            <lower>-1.57</lower>
            <upper>1.57</upper>
            <effort>200</effort>
            <velocity>3</velocity>
          </limit>
          <dynamics>
            <damping>10</damping>
            <friction>1</friction>
            <spring_reference>0</spring_reference>
            <spring_stiffness>0</spring_stiffness>
          </dynamics>
        </axis>
      </joint>
      <link name='upper_arm_link'>
        <pose relative_to='shoulder_lift_joint'>0 0 0 0 -0 0</pose>
        <inertial>
          <pose>-0.21652 0.079293 0 0 -0 0</pose>
          <mass>8.393</mass>
          <inertia>
            <ixx>0.0063671</ixx>
            <ixy>-9.2154e-12</ixy>
            <ixz>9.0018e-07</ixz>
            <iyy>0.021824</iyy>
            <iyz>-2.2572e-07</iyz>
            <izz>0.021327</izz>
          </inertia>
        </inertial>
        <collision name='upper_arm_link_collision'>
          <pose>0 0 0 0 -0 0</pose>
          <geometry>
            <mesh>
              <scale>1 1 1</scale>
              <uri>/mnt/Storage/Documents/MIT/Books/Robotics-2_Lab/Mini_Project/src/ur5/meshes/upper_arm_link.STL</uri>
            </mesh>
          </geometry>
          <surface>
            <contact>
              <ode/>
            </contact>
            <friction>
              <ode/>
              <torsional>
                <ode/>
              </torsional>
            </friction>
            <bounce/>
          </surface>
          <max_contacts>10</max_contacts>
        </collision>
        <visual name='upper_arm_link_visual'>
          <pose>0 0 0 0 -0 0</pose>
          <geometry>
            <mesh>
              <scale>1 1 1</scale>
              <uri>/mnt/Storage/Documents/MIT/Books/Robotics-2_Lab/Mini_Project/src/ur5/meshes/upper_arm_link.STL</uri>
            </mesh>
          </geometry>
          <material>
            <script>
              <name>Gazebo/White</name>
              <uri>file://media/materials/scripts/gazebo.material</uri>
            </script>
          </material>
        </visual>
        <self_collide>1</self_collide>
        <enable_wind>0</enable_wind>
        <kinematic>0</kinematic>
      </link>
      <joint name='elbow_joint' type='revolute'>
        <pose relative_to='upper_arm_link'>-0.425 0 0 0 -0 0</pose>
        <parent>upper_arm_link</parent>
        <child>forearm_link</child>
        <axis>
          <xyz>0 1 0</xyz>
          <limit>
            <lower>-6.2832</lower>
            <upper>6.2832</upper>
            <effort>200</effort>
            <velocity>3</velocity>
          </limit>
          <dynamics>
            <damping>10</damping>
            <friction>1</friction>
            <spring_reference>0</spring_reference>
            <spring_stiffness>0</spring_stiffness>
          </dynamics>
        </axis>
      </joint>
      <link name='forearm_link'>
        <pose relative_to='elbow_joint'>0 0 0 0 -0 0</pose>
        <inertial>
          <pose>-0.1739 -0.033049 -3e-06 0 -0 0</pose>
          <mass>2.275</mass>
          <inertia>
            <ixx>0.002241</ixx>
            <ixy>-0.00011285</ixy>
            <ixz>4.2229e-07</ixz>
            <iyy>0.011808</iyy>
            <iyz>-2.6928e-07</iyz>
            <izz>0.011655</izz>
          </inertia>
        </inertial>
        <collision name='forearm_link_collision'>
          <pose>0 0 0 0 -0 0</pose>
          <geometry>
            <mesh>
              <scale>1 1 1</scale>
              <uri>/mnt/Storage/Documents/MIT/Books/Robotics-2_Lab/Mini_Project/src/ur5/meshes/forearm_link.STL</uri>
            </mesh>
          </geometry>
          <surface>
            <contact>
              <ode/>
            </contact>
            <friction>
              <ode/>
              <torsional>
                <ode/>
              </torsional>
            </friction>
            <bounce/>
          </surface>
          <max_contacts>10</max_contacts>
        </collision>
        <visual name='forearm_link_visual'>
          <pose>0 0 0 0 -0 0</pose>
          <geometry>
            <mesh>
              <scale>1 1 1</scale>
              <uri>/mnt/Storage/Documents/MIT/Books/Robotics-2_Lab/Mini_Project/src/ur5/meshes/forearm_link.STL</uri>
            </mesh>
          </geometry>
          <material>
            <script>
              <name>Gazebo/White</name>
              <uri>file://media/materials/scripts/gazebo.material</uri>
            </script>
          </material>
        </visual>
        <self_collide>1</self_collide>
        <enable_wind>0</enable_wind>
        <kinematic>0</kinematic>
      </link>
      <joint name='wrist_1_joint' type='revolute'>
        <pose relative_to='forearm_link'>-0.39225 0 0 0 -0 0</pose>
        <parent>forearm_link</parent>
        <child>wrist_1_link</child>
        <axis>
          <xyz>0 -1 0</xyz>
          <limit>
            <lower>-6.2832</lower>
            <upper>6.2832</upper>
            <effort>200</effort>
            <velocity>3</velocity>
          </limit>
          <dynamics>
            <damping>10</damping>
            <friction>1</friction>
            <spring_reference>0</spring_reference>
            <spring_stiffness>0</spring_stiffness>
          </dynamics>
        </axis>
      </joint>
      <link name='wrist_1_link'>
        <pose relative_to='wrist_1_joint'>0 0 0 0 -0 0</pose>
        <inertial>
          <pose>0.003753 0.044978 1.3e-05 0 -0 0</pose>
          <mass>1.219</mass>
          <inertia>
            <ixx>0.00041141</ixx>
            <ixy>4.2784e-05</ixy>
            <ixz>-2.8598e-07</ixz>
            <iyy>0.00036744</iyy>
            <iyz>4.089e-07</iyz>
            <izz>0.000387</izz>
          </inertia>
        </inertial>
        <collision name='wrist_1_link_collision'>
          <pose>0 0 0 0 -0 0</pose>
          <geometry>
            <mesh>
              <scale>1 1 1</scale>
              <uri>/mnt/Storage/Documents/MIT/Books/Robotics-2_Lab/Mini_Project/src/ur5/meshes/wrist_1_link.STL</uri>
            </mesh>
          </geometry>
          <surface>
            <contact>
              <ode/>
            </contact>
            <friction>
              <ode/>
              <torsional>
                <ode/>
              </torsional>
            </friction>
            <bounce/>
          </surface>
          <max_contacts>10</max_contacts>
        </collision>
        <visual name='wrist_1_link_visual'>
          <pose>0 0 0 0 -0 0</pose>
          <geometry>
            <mesh>
              <scale>1 1 1</scale>
              <uri>/mnt/Storage/Documents/MIT/Books/Robotics-2_Lab/Mini_Project/src/ur5/meshes/wrist_1_link.STL</uri>
            </mesh>
          </geometry>
          <material>
            <script>
              <name>Gazebo/White</name>
              <uri>file://media/materials/scripts/gazebo.material</uri>
            </script>
          </material>
        </visual>
        <self_collide>1</self_collide>
        <enable_wind>0</enable_wind>
        <kinematic>0</kinematic>
      </link>
      <joint name='wrist_2_joint' type='revolute'>
        <pose relative_to='wrist_1_link'>0 0.056149 0 0 -0 0</pose>
        <parent>wrist_1_link</parent>
        <child>wrist_2_link</child>
        <axis>
          <xyz>1 0 0</xyz>
          <limit>
            <lower>-6.2832</lower>
            <upper>6.2832</upper>
            <effort>200</effort>
            <velocity>3</velocity>
          </limit>
          <dynamics>
            <damping>10</damping>
            <friction>1</friction>
            <spring_reference>0</spring_reference>
            <spring_stiffness>0</spring_stiffness>
          </dynamics>
        </axis>
      </joint>
      <link name='wrist_2_link'>
        <pose relative_to='wrist_2_joint'>0 0 0 0 -0 0</pose>
        <inertial>
          <pose>-0.083749 -0.003753 -1.2e-05 0 -0 0</pose>
          <mass>1.219</mass>
          <inertia>
            <ixx>0.00036744</ixx>
            <ixy>4.2782e-05</ixy>
            <ixz>4.1013e-07</ixz>
            <iyy>0.0004114</iyy>
            <iyz>-2.8709e-07</iyz>
            <izz>0.000387</izz>
          </inertia>
        </inertial>
        <collision name='wrist_2_link_collision'>
          <pose>0 0 0 0 -0 0</pose>
          <geometry>
            <mesh>
              <scale>1 1 1</scale>
              <uri>/mnt/Storage/Documents/MIT/Books/Robotics-2_Lab/Mini_Project/src/ur5/meshes/wrist_2_link.STL</uri>
            </mesh>
          </geometry>
          <surface>
            <contact>
              <ode/>
            </contact>
            <friction>
              <ode/>
              <torsional>
                <ode/>
              </torsional>
            </friction>
            <bounce/>
          </surface>
          <max_contacts>10</max_contacts>
        </collision>
        <visual name='wrist_2_link_visual'>
          <pose>0 0 0 0 -0 0</pose>
          <geometry>
            <mesh>
              <scale>1 1 1</scale>
              <uri>/mnt/Storage/Documents/MIT/Books/Robotics-2_Lab/Mini_Project/src/ur5/meshes/wrist_2_link.STL</uri>
            </mesh>
          </geometry>
          <material>
            <script>
              <name>Gazebo/White</name>
              <uri>file://media/materials/scripts/gazebo.material</uri>
            </script>
          </material>
        </visual>
        <self_collide>1</self_collide>
        <enable_wind>0</enable_wind>
        <kinematic>0</kinematic>
      </link>
      <joint name='wrist_3_joint' type='revolute'>
        <pose relative_to='wrist_2_link'>-0.09492 0.041547 0 -3.14159 -0 -3.14159</pose>
        <parent>wrist_2_link</parent>
        <child>wrist_3_link</child>
        <axis>
          <xyz>0 -1 0</xyz>
          <limit>
            <lower>-6.2832</lower>
            <upper>6.2832</upper>
            <effort>100</effort>
            <velocity>3</velocity>
          </limit>
          <dynamics>
            <damping>10</damping>
            <friction>1</friction>
            <spring_reference>0</spring_reference>
            <spring_stiffness>0</spring_stiffness>
          </dynamics>
        </axis>
      </joint>
      <link name='wrist_3_link'>
        <pose relative_to='wrist_3_joint'>0 0 0 0 -0 0</pose>
        <inertial>
          <pose>-7.6e-05 0.018225 0.00012 0 -0 0</pose>
          <mass>0.18831</mass>
          <inertia>
            <ixx>6.95191e-05</ixx>
            <ixy>5.6361e-08</ixy>
            <ixz>-3.20038e-07</ixz>
            <iyy>0.000117136</iyy>
            <iyz>-8.73543e-08</iyz>
            <izz>6.98172e-05</izz>
          </inertia>
        </inertial>
        <collision name='wrist_3_link_collision'>
          <pose>0 0 0 0 -0 0</pose>
          <geometry>
            <mesh>
              <scale>1 1 1</scale>
              <uri>/mnt/Storage/Documents/MIT/Books/Robotics-2_Lab/Mini_Project/src/ur5/meshes/wrist_3_link.STL</uri>
            </mesh>
          </geometry>
          <surface>
            <contact>
              <ode/>
            </contact>
            <friction>
              <ode/>
              <torsional>
                <ode/>
              </torsional>
            </friction>
            <bounce/>
          </surface>
          <max_contacts>10</max_contacts>
        </collision>
        <collision name='wrist_3_link_fixed_joint_lump__camera_link_collision_1'>
          <pose>0.04 0.02 0 0 -0 0</pose>
          <geometry>
            <box>
              <size>0.02 0.02 0.02</size>
            </box>
          </geometry>
          <surface>
            <contact>
              <ode/>
            </contact>
            <friction>
              <ode/>
              <torsional>
                <ode/>
              </torsional>
            </friction>
            <bounce/>
          </surface>
          <max_contacts>10</max_contacts>
        </collision>
        <visual name='wrist_3_link_visual'>
          <pose>0 0 0 0 -0 0</pose>
          <geometry>
            <mesh>
              <scale>1 1 1</scale>
              <uri>/mnt/Storage/Documents/MIT/Books/Robotics-2_Lab/Mini_Project/src/ur5/meshes/wrist_3_link.STL</uri>
            </mesh>
          </geometry>
          <material>
            <script>
              <name>Gazebo/Red</name>
              <uri>file://media/materials/scripts/gazebo.material</uri>
            </script>
          </material>
        </visual>
        <visual name='wrist_3_link_fixed_joint_lump__camera_link_visual_1'>
          <pose>0.04 0.02 0 0 -0 0</pose>
          <geometry>
            <box>
              <size>0.02 0.02 0.02</size>
            </box>
          </geometry>
          <material>
            <script>
              <name>Gazebo/Black</name>
              <uri>file://media/materials/scripts/gazebo.material</uri>
            </script>
          </material>
        </visual>
        <visual name='wrist_3_link_fixed_joint_lump__vacuum_gripper1_visual_2'>
          <pose>0.01 0.04 0 1.57 -0 0</pose>
          <geometry>
            <cylinder>
              <length>0.01</length>
              <radius>0.005</radius>
            </cylinder>
          </geometry>
          <material>
            <script>
              <name>Gazebo/Black</name>
              <uri>file://media/materials/scripts/gazebo.material</uri>
            </script>
          </material>
        </visual>
        <visual name='wrist_3_link_fixed_joint_lump__vacuum_gripper2_visual_3'>
          <pose>-0.01 0.04 0 1.57 -0 0</pose>
          <geometry>
            <cylinder>
              <length>0.01</length>
              <radius>0.005</radius>
            </cylinder>
          </geometry>
          <material>
            <script>
              <name>Gazebo/Black</name>
              <uri>file://media/materials/scripts/gazebo.material</uri>
            </script>
          </material>
        </visual>
        <visual name='wrist_3_link_fixed_joint_lump__vacuum_gripper3_visual_4'>
          <pose>0 0.04 0.01 1.57 -0 0</pose>
          <geometry>
            <cylinder>
              <length>0.01</length>
              <radius>0.005</radius>
            </cylinder>
          </geometry>
          <material>
            <script>
              <name>Gazebo/Black</name>
              <uri>file://media/materials/scripts/gazebo.material</uri>
            </script>
          </material>
        </visual>
        <visual name='wrist_3_link_fixed_joint_lump__vacuum_gripper4_visual_5'>
          <pose>0 0.04 -0.01 1.57 -0 0</pose>
          <geometry>
            <cylinder>
              <length>0.01</length>
              <radius>0.005</radius>
            </cylinder>
          </geometry>
          <material>
            <script>
              <name>Gazebo/Black</name>
              <uri>file://media/materials/scripts/gazebo.material</uri>
            </script>
          </material>
        </visual>
        <self_collide>1</self_collide>
        <enable_wind>0</enable_wind>
        <kinematic>0</kinematic>
      </link>
      <plugin name='gazebo_ros_vacuum_gripper1' filename='libgazebo_ros_vacuum_gripper.so'>
        <link_name>vacuum_gripper1</link_name>
        <topicName>grasping1</topicName>
        <maxForce>50</maxForce>
        <maxDistance>0.05</maxDistance>
        <minDistance>0.01</minDistance>
        <bodyName>wrist_3_link</bodyName>
        <xyzOffset>-0.01 -0.04 0</xyzOffset>
        <rpyOffset>-1.57 0 0</rpyOffset>
      </plugin>
      <plugin name='gazebo_ros_vacuum_gripper2' filename='libgazebo_ros_vacuum_gripper.so'>
        <link_name>vacuum_gripper2</link_name>
        <topicName>grasping2</topicName>
        <maxForce>50</maxForce>
        <maxDistance>0.05</maxDistance>
        <minDistance>0.01</minDistance>
        <bodyName>wrist_3_link</bodyName>
        <xyzOffset>0.01 -0.04 0</xyzOffset>
        <rpyOffset>-1.57 0 0</rpyOffset>
      </plugin>
      <plugin name='gazebo_ros_vacuum_gripper3' filename='libgazebo_ros_vacuum_gripper.so'>
        <link_name>vacuum_gripper3</link_name>
        <topicName>grasping3</topicName>
        <maxForce>50</maxForce>
        <maxDistance>0.05</maxDistance>
        <minDistance>0.01</minDistance>
        <bodyName>wrist_3_link</bodyName>
        <xyzOffset>0 -0.04 -0.01</xyzOffset>
        <rpyOffset>-1.57 0 0</rpyOffset>
      </plugin>
      <plugin name='gazebo_ros_vacuum_gripper4' filename='libgazebo_ros_vacuum_gripper.so'>
        <link_name>vacuum_gripper4</link_name>
        <topicName>grasping4</topicName>
        <maxForce>50</maxForce>
        <maxDistance>0.05</maxDistance>
        <minDistance>0.01</minDistance>
        <bodyName>wrist_3_link</bodyName>
        <xyzOffset>0 -0.04 0.01</xyzOffset>
        <rpyOffset>-1.57 0 0</rpyOffset>
      </plugin>
      <static>0</static>
      <plugin name='gazebo_ros2_control' filename='libgazebo_ros2_control.so'>
        <robot_sim_type>gazebo_ros2_control/GazeboSystem</robot_sim_type>
        <parameters>/mnt/Storage/Documents/MIT/Books/Robotics-2_Lab/Mini_Project/src/ur5/config/ur5_control.yaml</parameters>
      </plugin>
      <pose>0 0 0 0 -0 0</pose>
    </model>
    <state world_name='default'>
      <sim_time>159 777000000</sim_time>
      <real_time>573 143139690</real_time>
      <wall_time>1729145907 736917525</wall_time>
      <iterations>159777</iterations>
      <model name='conveyor_belt'>
        <pose>-0.5 0 -0.25 0 -0 0</pose>
        <scale>1 1 1</scale>
        <model name='conveyorbelt_fixed'>
          <pose>-0.5 0 -0.25 0 -0 0</pose>
          <scale>1 1 1</scale>
          <link name='belt_visual'>
            <pose>-0.5 0 -0.25 0 -0 0</pose>
            <velocity>0 0 0 0 -0 0</velocity>
            <acceleration>0 0 0 0 -0 0</acceleration>
            <wrench>0 0 0 0 -0 0</wrench>
          </link>
        </model>
        <model name='conveyorbelt_moving'>
          <pose>-0.5 0 0.491855 0 -0 0</pose>
          <scale>1 1 1</scale>
          <link name='belt_moving'>
            <pose>6e-06 0.009915 0.74106 0.002582 -0.00033 3e-06</pose>
            <velocity>0.008354 -0.019743 -0.005333 -0.463468 -0.010686 -0.152301</velocity>
            <acceleration>8.35411 -19.743 -5.3335 0 -0 0</acceleration>
            <wrench>835.411 -1974.3 -533.35 0 -0 0</wrench>
          </link>
        </model>
      </model>
      <model name='ground_plane'>
        <pose>0 0 0 0 -0 0</pose>
        <scale>1 1 1</scale>
        <link name='link'>
          <pose>0 0 0 0 -0 0</pose>
          <velocity>0 0 0 0 -0 0</velocity>
          <acceleration>0 0 0 0 -0 0</acceleration>
          <wrench>0 0 0 0 -0 0</wrench>
        </link>
      </model>
      <model name='ur5'>
        <pose>-0.000848 -4.8e-05 0.000605 -0.003422 0.023798 -0.014955</pose>
        <scale>1 1 1</scale>
        <link name='base_link'>
          <pose>-0.000848 -4.8e-05 0.000605 -0.003422 0.023798 -0.014955</pose>
          <velocity>-0.022861 0.114519 -0.070951 -1.4731 1.29378 -1.44708</velocity>
          <acceleration>62.9643 -52.9877 6.02707 -0.463097 0.339108 -0.110337</acceleration>
          <wrench>251.857 -211.951 24.1083 0 -0 0</wrench>
        </link>
        <link name='forearm_link'>
          <pose>0.105332 0.230532 0.400956 2.20216 1.14507 -0.003772</pose>
          <velocity>0.240612 6.25557 -3.68455 -1.94372 0.701522 0.971694</velocity>
          <acceleration>1614.58 3690.58 44.9247 -1.98709 1.02974 1.78491</acceleration>
          <wrench>3673.18 8396.08 102.204 0 -0 0</wrench>
        </link>
        <link name='shoulder_link'>
          <pose>-0.006733 -0.000321 0.009681 2.42923 1.28671 0.272183</pose>
          <velocity>-0.250147 0.84968 -0.087406 -0.817384 -0.220869 1.55201</velocity>
          <acceleration>-326.813 1685.36 168.485 -0.099003 1.11834 -0.120891</acceleration>
          <wrench>-1209.21 6235.82 623.394 0 -0 0</wrench>
        </link>
        <link name='upper_arm_link'>
          <pose>0.005729 -0.036352 0.097068 0.373635 0.796907 -1.92431</pose>
          <velocity>0.896006 2.05244 0.584041 -1.35106 1.10987 -2.36344</velocity>
          <acceleration>317.64 2036.18 294.534 2.26692 -0.216104 0.168435</acceleration>
          <wrench>2665.95 17089.7 2472.03 0 -0 0</wrench>
        </link>
        <link name='wrist_1_link'>
          <pose>-0.042947 0.248862 0.765403 -0.969007 1.50096 3.05387</pose>
          <velocity>2.19418 2.5254 -5.05232 0.063688 0.377491 -2.94116</velocity>
          <acceleration>-506.198 -3365.5 -1804.78 -1.80652 0.733948 2.91688</acceleration>
          <wrench>-617.056 -4102.54 -2200.03 0 -0 0</wrench>
        </link>
        <link name='wrist_2_link'>
          <pose>-0.002887 0.218333 0.776211 -0.762713 1.20487 -2.38882</pose>
          <velocity>2.6104 1.82607 -5.88414 -3.1134 1.25836 -3.10718</velocity>
          <acceleration>-4631.04 -4759.73 -2715.86 2.03475 -1.07989 -0.954324</acceleration>
          <wrench>-5645.24 -5802.11 -3310.63 0 -0 0</wrench>
        </link>
        <link name='wrist_3_link'>
          <pose>0.064496 0.237947 0.853564 -0.572302 -1.04094 -1.14403</pose>
          <velocity>-2.15611 2.83832 -2.52706 1.58043 0.086812 -1.80508</velocity>
          <acceleration>-4358.22 -1977.24 271.208 -0.663635 0.995712 1.11459</acceleration>
          <wrench>-820.697 -372.334 51.0712 0 -0 0</wrench>
        </link>
      </model>
      <light name='sun'>
        <pose>0 0 10 0 -0 0</pose>
      </light>
    </state>
    <gui fullscreen='0'>
      <camera name='user_camera'>
        <pose>0.228776 -4.49304 2.60785 -0 0.383643 1.31619</pose>
        <view_controller>orbit</view_controller>
        <projection_type>perspective</projection_type>
      </camera>
    </gui>
  </world>
</sdf>
