<sdf version='1.7'>
  <world name='default'>
    <light name='sun' type='directional'>
      <cast_shadows>1</cast_shadows>
      <pose>0 0 10 0 -0 0</pose>
      <diffuse>0.8 0.8 0.8 1</diffuse>
      <specular>0.2 0.2 0.2 1</specular>
      <attenuation>
        <range>1000</range>
        <constant>0.9</constant>
        <linear>0.01</linear>
        <quadratic>0.001</quadratic>
      </attenuation>
      <direction>-0.5 0.1 -0.9</direction>
      <spot>
        <inner_angle>0</inner_angle>
        <outer_angle>0</outer_angle>
        <falloff>0</falloff>
      </spot>
    </light>
    <model name='ground_plane'>
      <static>1</static>
      <link name='link'>
        <collision name='collision'>
          <geometry>
            <plane>
              <normal>0 0 1</normal>
              <size>100 100</size>
            </plane>
          </geometry>
          <surface>
            <friction>
              <ode>
                <mu>100</mu>
                <mu2>50</mu2>
              </ode>
              <torsional>
                <ode/>
              </torsional>
            </friction>
            <contact>
              <ode/>
            </contact>
            <bounce/>
          </surface>
          <max_contacts>10</max_contacts>
        </collision>
        <visual name='visual'>
          <cast_shadows>0</cast_shadows>
          <geometry>
            <plane>
              <normal>0 0 1</normal>
              <size>100 100</size>
            </plane>
          </geometry>
          <material>
            <script>
              <uri>file://media/materials/scripts/gazebo.material</uri>
              <name>Gazebo/Grey</name>
            </script>
          </material>
        </visual>
        <self_collide>0</self_collide>
        <enable_wind>0</enable_wind>
        <kinematic>0</kinematic>
      </link>
    </model>
    <gravity>0 0 -9.8</gravity>
    <magnetic_field>6e-06 2.3e-05 -4.2e-05</magnetic_field>
    <atmosphere type='adiabatic'/>
    <physics type='ode'>
      <max_step_size>0.001</max_step_size>
      <real_time_factor>1</real_time_factor>
      <real_time_update_rate>1000</real_time_update_rate>
    </physics>
    <scene>
      <ambient>0.4 0.4 0.4 1</ambient>
      <background>0.7 0.7 0.7 1</background>
      <shadows>1</shadows>
    </scene>
    <audio>
      <device>default</device>
    </audio>
    <wind/>
    <spherical_coordinates>
      <surface_model>EARTH_WGS84</surface_model>
      <latitude_deg>0</latitude_deg>
      <longitude_deg>0</longitude_deg>
      <elevation>0</elevation>
      <heading_deg>0</heading_deg>
    </spherical_coordinates>
    <model name='ur5'>
      <joint name='world_to_base' type='fixed'>
        <pose relative_to='__model__'>0 0 0 0 -0 0</pose>
        <parent>world</parent>
        <child>base_link</child>
      </joint>
      <link name='base_link'>
        <pose relative_to='world_to_base'>0 0 0 0 -0 0</pose>
        <inertial>
          <pose>-0.000367 -0.000368 0.016561 0 -0 0</pose>
          <mass>4</mass>
          <inertia>
            <ixx>0.00060258</ixx>
            <ixy>1.7502e-05</ixy>
            <ixz>1.5277e-06</ixz>
            <iyy>0.00060261</iyy>
            <iyz>1.5241e-06</iyz>
            <izz>0.0010709</izz>
          </inertia>
        </inertial>
        <collision name='base_link_collision'>
          <pose>0 0 0 0 -0 0</pose>
          <geometry>
            <mesh>
              <scale>1 1 1</scale>
              <uri>/mnt/Storage/Documents/MIT/Books/Robotics-2_Lab/Mini_Project/src/ur5/meshes/base_link.STL</uri>
            </mesh>
          </geometry>
          <surface>
            <contact>
              <ode/>
            </contact>
            <friction>
              <ode/>
              <torsional>
                <ode/>
              </torsional>
            </friction>
            <bounce/>
          </surface>
          <max_contacts>10</max_contacts>
        </collision>
        <visual name='base_link_visual'>
          <pose>0 0 0 0 -0 0</pose>
          <geometry>
            <mesh>
              <scale>1 1 1</scale>
              <uri>/mnt/Storage/Documents/MIT/Books/Robotics-2_Lab/Mini_Project/src/ur5/meshes/base_link.STL</uri>
            </mesh>
          </geometry>
          <material>
            <script>
              <name>Gazebo/Yellow</name>
              <uri>file://media/materials/scripts/gazebo.material</uri>
            </script>
          </material>
        </visual>
        <self_collide>0</self_collide>
        <enable_wind>0</enable_wind>
        <kinematic>0</kinematic>
      </link>
      <joint name='shoulder_pan_joint' type='revolute'>
        <pose relative_to='base_link'>0 0 0.009992 -1.57079 1.57079 3.14159</pose>
        <parent>base_link</parent>
        <child>shoulder_link</child>
        <axis>
          <xyz>1 0 0</xyz>
          <limit>
            <lower>-6.2832</lower>
            <upper>6.2832</upper>
            <effort>300</effort>
            <velocity>3</velocity>
          </limit>
          <dynamics>
            <damping>10</damping>
            <friction>1</friction>
            <spring_reference>0</spring_reference>
            <spring_stiffness>0</spring_stiffness>
          </dynamics>
        </axis>
      </joint>
      <link name='shoulder_link'>
        <pose relative_to='shoulder_pan_joint'>0 0 0 0 -0 0</pose>
        <inertial>
          <pose>-0.078966 0.016439 -6e-06 0 -0 0</pose>
          <mass>3.7</mass>
          <inertia>
            <ixx>0.0028298</ixx>
            <ixy>0.00031932</ixy>
            <ixz>-1.3132e-07</ixz>
            <iyy>0.002538</iyy>
            <iyz>4.4907e-07</iyz>
            <izz>0.0026207</izz>
          </inertia>
        </inertial>
        <collision name='shoulder_link_collision'>
          <pose>0 0 0 0 -0 0</pose>
          <geometry>
            <mesh>
              <scale>1 1 1</scale>
              <uri>/mnt/Storage/Documents/MIT/Books/Robotics-2_Lab/Mini_Project/src/ur5/meshes/shoulder_link.STL</uri>
            </mesh>
          </geometry>
          <surface>
            <contact>
              <ode/>
            </contact>
            <friction>
              <ode/>
              <torsional>
                <ode/>
              </torsional>
            </friction>
            <bounce/>
          </surface>
          <max_contacts>10</max_contacts>
        </collision>
        <visual name='shoulder_link_visual'>
          <pose>0 0 0 0 -0 0</pose>
          <geometry>
            <mesh>
              <scale>1 1 1</scale>
              <uri>/mnt/Storage/Documents/MIT/Books/Robotics-2_Lab/Mini_Project/src/ur5/meshes/shoulder_link.STL</uri>
            </mesh>
          </geometry>
          <material>
            <script>
              <name>Gazebo/Yellow</name>
              <uri>file://media/materials/scripts/gazebo.material</uri>
            </script>
          </material>
        </visual>
        <self_collide>1</self_collide>
        <enable_wind>0</enable_wind>
        <kinematic>0</kinematic>
      </link>
      <joint name='shoulder_lift_joint' type='revolute'>
        <pose relative_to='shoulder_link'>-0.080008 0.053821 0 0 -0 0</pose>
        <parent>shoulder_link</parent>
        <child>upper_arm_link</child>
        <axis>
          <xyz>0 -1 0</xyz>
          <limit>
            <lower>-1.57</lower>
            <upper>1.57</upper>
            <effort>200</effort>
            <velocity>3</velocity>
          </limit>
          <dynamics>
            <damping>10</damping>
            <friction>1</friction>
            <spring_reference>0</spring_reference>
            <spring_stiffness>0</spring_stiffness>
          </dynamics>
        </axis>
      </joint>
      <link name='upper_arm_link'>
        <pose relative_to='shoulder_lift_joint'>0 0 0 0 -0 0</pose>
        <inertial>
          <pose>-0.21652 0.079293 0 0 -0 0</pose>
          <mass>8.393</mass>
          <inertia>
            <ixx>0.0063671</ixx>
            <ixy>-9.2154e-12</ixy>
            <ixz>9.0018e-07</ixz>
            <iyy>0.021824</iyy>
            <iyz>-2.2572e-07</iyz>
            <izz>0.021327</izz>
          </inertia>
        </inertial>
        <collision name='upper_arm_link_collision'>
          <pose>0 0 0 0 -0 0</pose>
          <geometry>
            <mesh>
              <scale>1 1 1</scale>
              <uri>/mnt/Storage/Documents/MIT/Books/Robotics-2_Lab/Mini_Project/src/ur5/meshes/upper_arm_link.STL</uri>
            </mesh>
          </geometry>
          <surface>
            <contact>
              <ode/>
            </contact>
            <friction>
              <ode/>
              <torsional>
                <ode/>
              </torsional>
            </friction>
            <bounce/>
          </surface>
          <max_contacts>10</max_contacts>
        </collision>
        <visual name='upper_arm_link_visual'>
          <pose>0 0 0 0 -0 0</pose>
          <geometry>
            <mesh>
              <scale>1 1 1</scale>
              <uri>/mnt/Storage/Documents/MIT/Books/Robotics-2_Lab/Mini_Project/src/ur5/meshes/upper_arm_link.STL</uri>
            </mesh>
          </geometry>
          <material>
            <script>
              <name>Gazebo/White</name>
              <uri>file://media/materials/scripts/gazebo.material</uri>
            </script>
          </material>
        </visual>
        <self_collide>1</self_collide>
        <enable_wind>0</enable_wind>
        <kinematic>0</kinematic>
      </link>
      <joint name='elbow_joint' type='revolute'>
        <pose relative_to='upper_arm_link'>-0.425 0 0 0 -0 0</pose>
        <parent>upper_arm_link</parent>
        <child>forearm_link</child>
        <axis>
          <xyz>0 1 0</xyz>
          <limit>
            <lower>-6.2832</lower>
            <upper>6.2832</upper>
            <effort>200</effort>
            <velocity>3</velocity>
          </limit>
          <dynamics>
            <damping>10</damping>
            <friction>1</friction>
            <spring_reference>0</spring_reference>
            <spring_stiffness>0</spring_stiffness>
          </dynamics>
        </axis>
      </joint>
      <link name='forearm_link'>
        <pose relative_to='elbow_joint'>0 0 0 0 -0 0</pose>
        <inertial>
          <pose>-0.1739 -0.033049 -3e-06 0 -0 0</pose>
          <mass>2.275</mass>
          <inertia>
            <ixx>0.002241</ixx>
            <ixy>-0.00011285</ixy>
            <ixz>4.2229e-07</ixz>
            <iyy>0.011808</iyy>
            <iyz>-2.6928e-07</iyz>
            <izz>0.011655</izz>
          </inertia>
        </inertial>
        <collision name='forearm_link_collision'>
          <pose>0 0 0 0 -0 0</pose>
          <geometry>
            <mesh>
              <scale>1 1 1</scale>
              <uri>/mnt/Storage/Documents/MIT/Books/Robotics-2_Lab/Mini_Project/src/ur5/meshes/forearm_link.STL</uri>
            </mesh>
          </geometry>
          <surface>
            <contact>
              <ode/>
            </contact>
            <friction>
              <ode/>
              <torsional>
                <ode/>
              </torsional>
            </friction>
            <bounce/>
          </surface>
          <max_contacts>10</max_contacts>
        </collision>
        <visual name='forearm_link_visual'>
          <pose>0 0 0 0 -0 0</pose>
          <geometry>
            <mesh>
              <scale>1 1 1</scale>
              <uri>/mnt/Storage/Documents/MIT/Books/Robotics-2_Lab/Mini_Project/src/ur5/meshes/forearm_link.STL</uri>
            </mesh>
          </geometry>
          <material>
            <script>
              <name>Gazebo/White</name>
              <uri>file://media/materials/scripts/gazebo.material</uri>
            </script>
          </material>
        </visual>
        <self_collide>1</self_collide>
        <enable_wind>0</enable_wind>
        <kinematic>0</kinematic>
      </link>
      <joint name='wrist_1_joint' type='revolute'>
        <pose relative_to='forearm_link'>-0.39225 0 0 0 -0 0</pose>
        <parent>forearm_link</parent>
        <child>wrist_1_link</child>
        <axis>
          <xyz>0 -1 0</xyz>
          <limit>
            <lower>-6.2832</lower>
            <upper>6.2832</upper>
            <effort>200</effort>
            <velocity>3</velocity>
          </limit>
          <dynamics>
            <damping>10</damping>
            <friction>1</friction>
            <spring_reference>0</spring_reference>
            <spring_stiffness>0</spring_stiffness>
          </dynamics>
        </axis>
      </joint>
      <link name='wrist_1_link'>
        <pose relative_to='wrist_1_joint'>0 0 0 0 -0 0</pose>
        <inertial>
          <pose>0.003753 0.044978 1.3e-05 0 -0 0</pose>
          <mass>1.219</mass>
          <inertia>
            <ixx>0.00041141</ixx>
            <ixy>4.2784e-05</ixy>
            <ixz>-2.8598e-07</ixz>
            <iyy>0.00036744</iyy>
            <iyz>4.089e-07</iyz>
            <izz>0.000387</izz>
          </inertia>
        </inertial>
        <collision name='wrist_1_link_collision'>
          <pose>0 0 0 0 -0 0</pose>
          <geometry>
            <mesh>
              <scale>1 1 1</scale>
              <uri>/mnt/Storage/Documents/MIT/Books/Robotics-2_Lab/Mini_Project/src/ur5/meshes/wrist_1_link.STL</uri>
            </mesh>
          </geometry>
          <surface>
            <contact>
              <ode/>
            </contact>
            <friction>
              <ode/>
              <torsional>
                <ode/>
              </torsional>
            </friction>
            <bounce/>
          </surface>
          <max_contacts>10</max_contacts>
        </collision>
        <visual name='wrist_1_link_visual'>
          <pose>0 0 0 0 -0 0</pose>
          <geometry>
            <mesh>
              <scale>1 1 1</scale>
              <uri>/mnt/Storage/Documents/MIT/Books/Robotics-2_Lab/Mini_Project/src/ur5/meshes/wrist_1_link.STL</uri>
            </mesh>
          </geometry>
          <material>
            <script>
              <name>Gazebo/White</name>
              <uri>file://media/materials/scripts/gazebo.material</uri>
            </script>
          </material>
        </visual>
        <self_collide>1</self_collide>
        <enable_wind>0</enable_wind>
        <kinematic>0</kinematic>
      </link>
      <joint name='wrist_2_joint' type='revolute'>
        <pose relative_to='wrist_1_link'>0 0.056149 0 0 -0 0</pose>
        <parent>wrist_1_link</parent>
        <child>wrist_2_link</child>
        <axis>
          <xyz>1 0 0</xyz>
          <limit>
            <lower>-6.2832</lower>
            <upper>6.2832</upper>
            <effort>200</effort>
            <velocity>3</velocity>
          </limit>
          <dynamics>
            <damping>10</damping>
            <friction>1</friction>
            <spring_reference>0</spring_reference>
            <spring_stiffness>0</spring_stiffness>
          </dynamics>
        </axis>
      </joint>
      <link name='wrist_2_link'>
        <pose relative_to='wrist_2_joint'>0 0 0 0 -0 0</pose>
        <inertial>
          <pose>-0.083749 -0.003753 -1.2e-05 0 -0 0</pose>
          <mass>1.219</mass>
          <inertia>
            <ixx>0.00036744</ixx>
            <ixy>4.2782e-05</ixy>
            <ixz>4.1013e-07</ixz>
            <iyy>0.0004114</iyy>
            <iyz>-2.8709e-07</iyz>
            <izz>0.000387</izz>
          </inertia>
        </inertial>
        <collision name='wrist_2_link_collision'>
          <pose>0 0 0 0 -0 0</pose>
          <geometry>
            <mesh>
              <scale>1 1 1</scale>
              <uri>/mnt/Storage/Documents/MIT/Books/Robotics-2_Lab/Mini_Project/src/ur5/meshes/wrist_2_link.STL</uri>
            </mesh>
          </geometry>
          <surface>
            <contact>
              <ode/>
            </contact>
            <friction>
              <ode/>
              <torsional>
                <ode/>
              </torsional>
            </friction>
            <bounce/>
          </surface>
          <max_contacts>10</max_contacts>
        </collision>
        <visual name='wrist_2_link_visual'>
          <pose>0 0 0 0 -0 0</pose>
          <geometry>
            <mesh>
              <scale>1 1 1</scale>
              <uri>/mnt/Storage/Documents/MIT/Books/Robotics-2_Lab/Mini_Project/src/ur5/meshes/wrist_2_link.STL</uri>
            </mesh>
          </geometry>
          <material>
            <script>
              <name>Gazebo/White</name>
              <uri>file://media/materials/scripts/gazebo.material</uri>
            </script>
          </material>
        </visual>
        <self_collide>1</self_collide>
        <enable_wind>0</enable_wind>
        <kinematic>0</kinematic>
      </link>
      <joint name='wrist_3_joint' type='revolute'>
        <pose relative_to='wrist_2_link'>-0.09492 0.041547 0 -3.14159 -0 -3.14159</pose>
        <parent>wrist_2_link</parent>
        <child>wrist_3_link</child>
        <axis>
          <xyz>0 -1 0</xyz>
          <limit>
            <lower>-6.2832</lower>
            <upper>6.2832</upper>
            <effort>100</effort>
            <velocity>3</velocity>
          </limit>
          <dynamics>
            <damping>10</damping>
            <friction>1</friction>
            <spring_reference>0</spring_reference>
            <spring_stiffness>0</spring_stiffness>
          </dynamics>
        </axis>
      </joint>
      <link name='wrist_3_link'>
        <pose relative_to='wrist_3_joint'>0 0 0 0 -0 0</pose>
        <inertial>
          <pose>-7.6e-05 0.018225 0.00012 0 -0 0</pose>
          <mass>0.18831</mass>
          <inertia>
            <ixx>6.95191e-05</ixx>
            <ixy>5.6361e-08</ixy>
            <ixz>-3.20038e-07</ixz>
            <iyy>0.000117136</iyy>
            <iyz>-8.73543e-08</iyz>
            <izz>6.98172e-05</izz>
          </inertia>
        </inertial>
        <collision name='wrist_3_link_collision'>
          <pose>0 0 0 0 -0 0</pose>
          <geometry>
            <mesh>
              <scale>1 1 1</scale>
              <uri>/mnt/Storage/Documents/MIT/Books/Robotics-2_Lab/Mini_Project/src/ur5/meshes/wrist_3_link.STL</uri>
            </mesh>
          </geometry>
          <surface>
            <contact>
              <ode/>
            </contact>
            <friction>
              <ode/>
              <torsional>
                <ode/>
              </torsional>
            </friction>
            <bounce/>
          </surface>
          <max_contacts>10</max_contacts>
        </collision>
        <collision name='wrist_3_link_fixed_joint_lump__camera_link_collision_1'>
          <pose>0.04 0.02 0 0 -0 0</pose>
          <geometry>
            <box>
              <size>0.02 0.02 0.02</size>
            </box>
          </geometry>
          <surface>
            <contact>
              <ode/>
            </contact>
            <friction>
              <ode/>
              <torsional>
                <ode/>
              </torsional>
            </friction>
            <bounce/>
          </surface>
          <max_contacts>10</max_contacts>
        </collision>
        <visual name='wrist_3_link_visual'>
          <pose>0 0 0 0 -0 0</pose>
          <geometry>
            <mesh>
              <scale>1 1 1</scale>
              <uri>/mnt/Storage/Documents/MIT/Books/Robotics-2_Lab/Mini_Project/src/ur5/meshes/wrist_3_link.STL</uri>
            </mesh>
          </geometry>
          <material>
            <script>
              <name>Gazebo/Red</name>
              <uri>file://media/materials/scripts/gazebo.material</uri>
            </script>
          </material>
        </visual>
        <visual name='wrist_3_link_fixed_joint_lump__camera_link_visual_1'>
          <pose>0.04 0.02 0 0 -0 0</pose>
          <geometry>
            <box>
              <size>0.02 0.02 0.02</size>
            </box>
          </geometry>
          <material>
            <script>
              <name>Gazebo/Black</name>
              <uri>file://media/materials/scripts/gazebo.material</uri>
            </script>
          </material>
        </visual>
        <visual name='wrist_3_link_fixed_joint_lump__vacuum_gripper1_visual_2'>
          <pose>0.01 0.04 0 1.57 -0 0</pose>
          <geometry>
            <cylinder>
              <length>0.01</length>
              <radius>0.005</radius>
            </cylinder>
          </geometry>
          <material>
            <script>
              <name>Gazebo/Black</name>
              <uri>file://media/materials/scripts/gazebo.material</uri>
            </script>
          </material>
        </visual>
        <visual name='wrist_3_link_fixed_joint_lump__vacuum_gripper2_visual_3'>
          <pose>-0.01 0.04 0 1.57 -0 0</pose>
          <geometry>
            <cylinder>
              <length>0.01</length>
              <radius>0.005</radius>
            </cylinder>
          </geometry>
          <material>
            <script>
              <name>Gazebo/Black</name>
              <uri>file://media/materials/scripts/gazebo.material</uri>
            </script>
          </material>
        </visual>
        <visual name='wrist_3_link_fixed_joint_lump__vacuum_gripper3_visual_4'>
          <pose>0 0.04 0.01 1.57 -0 0</pose>
          <geometry>
            <cylinder>
              <length>0.01</length>
              <radius>0.005</radius>
            </cylinder>
          </geometry>
          <material>
            <script>
              <name>Gazebo/Black</name>
              <uri>file://media/materials/scripts/gazebo.material</uri>
            </script>
          </material>
        </visual>
        <visual name='wrist_3_link_fixed_joint_lump__vacuum_gripper4_visual_5'>
          <pose>0 0.04 -0.01 1.57 -0 0</pose>
          <geometry>
            <cylinder>
              <length>0.01</length>
              <radius>0.005</radius>
            </cylinder>
          </geometry>
          <material>
            <script>
              <name>Gazebo/Black</name>
              <uri>file://media/materials/scripts/gazebo.material</uri>
            </script>
          </material>
        </visual>
        <self_collide>1</self_collide>
        <sensor name='camera1' type='camera'>
          <update_rate>30</update_rate>
          <camera name='head'>
            <horizontal_fov>1.39626</horizontal_fov>
            <image>
              <width>800</width>
              <height>800</height>
              <format>R8G8B8</format>
            </image>
            <clip>
              <near>0.02</near>
              <far>300</far>
            </clip>
            <noise>
              <type>gaussian</type>
              <mean>0</mean>
              <stddev>0.007</stddev>
            </noise>
          </camera>
          <plugin name='camera_controller' filename='libgazebo_ros_camera.so'>
            <alwaysOn>1</alwaysOn>
            <updateRate>0.0</updateRate>
            <cameraName>ur5/usbcam</cameraName>
            <imageTopicName>image_raw</imageTopicName>
            <cameraInfoTopicName>camera_info</cameraInfoTopicName>
            <frameName>camera_link_optical</frameName>
            <hackBaseline>0.0</hackBaseline>
            <distortionK1>0.0</distortionK1>
            <distortionK2>0.0</distortionK2>
            <distortionK3>0.0</distortionK3>
            <distortionT1>0.0</distortionT1>
            <distortionT2>0.0</distortionT2>
            <CxPrime>0</CxPrime>
            <Cx>0.0</Cx>
            <Cy>0.0</Cy>
            <focalLength>0.0</focalLength>
          </plugin>
          <pose>0.04 0.02 0 0 -0 0</pose>
        </sensor>
        <enable_wind>0</enable_wind>
        <kinematic>0</kinematic>
      </link>
      <plugin name='gazebo_ros_vacuum_gripper1' filename='libgazebo_ros_vacuum_gripper.so'>
        <link_name>vacuum_gripper1</link_name>
        <topicName>grasping1</topicName>
        <maxForce>50</maxForce>
        <maxDistance>0.05</maxDistance>
        <minDistance>0.01</minDistance>
        <bodyName>wrist_3_link</bodyName>
        <xyzOffset>-0.01 -0.04 0</xyzOffset>
        <rpyOffset>-1.57 0 0</rpyOffset>
      </plugin>
      <plugin name='gazebo_ros_vacuum_gripper2' filename='libgazebo_ros_vacuum_gripper.so'>
        <link_name>vacuum_gripper2</link_name>
        <topicName>grasping2</topicName>
        <maxForce>50</maxForce>
        <maxDistance>0.05</maxDistance>
        <minDistance>0.01</minDistance>
        <bodyName>wrist_3_link</bodyName>
        <xyzOffset>0.01 -0.04 0</xyzOffset>
        <rpyOffset>-1.57 0 0</rpyOffset>
      </plugin>
      <plugin name='gazebo_ros_vacuum_gripper3' filename='libgazebo_ros_vacuum_gripper.so'>
        <link_name>vacuum_gripper3</link_name>
        <topicName>grasping3</topicName>
        <maxForce>50</maxForce>
        <maxDistance>0.05</maxDistance>
        <minDistance>0.01</minDistance>
        <bodyName>wrist_3_link</bodyName>
        <xyzOffset>0 -0.04 -0.01</xyzOffset>
        <rpyOffset>-1.57 0 0</rpyOffset>
      </plugin>
      <plugin name='gazebo_ros_vacuum_gripper4' filename='libgazebo_ros_vacuum_gripper.so'>
        <link_name>vacuum_gripper4</link_name>
        <topicName>grasping4</topicName>
        <maxForce>50</maxForce>
        <maxDistance>0.05</maxDistance>
        <minDistance>0.01</minDistance>
        <bodyName>wrist_3_link</bodyName>
        <xyzOffset>0 -0.04 0.01</xyzOffset>
        <rpyOffset>-1.57 0 0</rpyOffset>
      </plugin>
      <static>0</static>
      <plugin name='gazebo_ros2_control' filename='libgazebo_ros2_control.so'>
        <robot_sim_type>gazebo_ros2_control/GazeboSystem</robot_sim_type>
        <parameters>/mnt/Storage/Documents/MIT/Books/Robotics-2_Lab/Mini_Project/src/ur5/config/ur5_control.yaml</parameters>
      </plugin>
      <pose>0 0 0 0 -0 0</pose>
    </model>
    <model name='conveyor_belt'>
      <model name='conveyorbelt_fixed'>
        <static>1</static>
        <link name='belt_visual'>
          <visual name='visual'>
            <geometry>
              <mesh>
                <scale>1 1 1</scale>
                <uri>model://conveyor_belt/meshes/conveyor_belt.dae</uri>
              </mesh>
            </geometry>
          </visual>
          <collision name='collision'>
            <geometry>
              <mesh>
                <scale>1 1 1</scale>
                <uri>model://conveyor_belt/meshes/conveyor_belt.dae</uri>
              </mesh>
            </geometry>
            <max_contacts>10</max_contacts>
            <surface>
              <contact>
                <ode/>
              </contact>
              <bounce/>
              <friction>
                <torsional>
                  <ode/>
                </torsional>
                <ode/>
              </friction>
            </surface>
            <origin xyz='0.0 0.0 0' rpy='0.0 0.0 0.0'/>
          </collision>
          <self_collide>0</self_collide>
          <enable_wind>0</enable_wind>
          <kinematic>0</kinematic>
        </link>
      </model>
      <model name='conveyorbelt_moving'>
        <allow_auto_disable>0</allow_auto_disable>
        <static>0</static>
        <pose>0 0 0.741 0 -0 0</pose>
        <link name='belt_moving'>
          <inertial>
            <mass>100</mass>
            <inertia>
              <ixx>0</ixx>
              <ixy>0</ixy>
              <ixz>0</ixz>
              <iyy>0</iyy>
              <iyz>0</iyz>
              <izz>0</izz>
            </inertia>
            <pose>0 0 0 0 -0 0</pose>
          </inertial>
          <collision name='belt_collision'>
            <geometry>
              <box>
                <size>0.425 1.2 1e-05</size>
              </box>
            </geometry>
            <surface>
              <friction>
                <ode>
                  <mu>100</mu>
                  <mu2>100</mu2>
                </ode>
                <torsional>
                  <coefficient>1000</coefficient>
                  <patch_radius>0.1</patch_radius>
                  <ode/>
                </torsional>
              </friction>
              <contact>
                <ode/>
              </contact>
              <bounce/>
            </surface>
            <max_contacts>10</max_contacts>
          </collision>
          <self_collide>0</self_collide>
          <enable_wind>0</enable_wind>
          <kinematic>0</kinematic>
        </link>
      </model>
      <joint name='belt_joint' type='prismatic'>
        <parent>conveyorbelt_fixed::belt_visual</parent>
        <child>conveyorbelt_moving::belt_moving</child>
        <axis>
          <xyz expressed_in='__model__'>0 1 0</xyz>
          <limit>
            <lower>0</lower>
            <upper>0.01</upper>
          </limit>
          <dynamics>
            <spring_reference>0</spring_reference>
            <spring_stiffness>0</spring_stiffness>
          </dynamics>
        </axis>
      </joint>
      <plugin name='ros2_conveyorbelt_plugin' filename='libros2_conveyorbelt_plugin.so'>
        <ros>
          <namespace/>
        </ros>
        <max_velocity>1.0</max_velocity>
        <publish_rate>1000</publish_rate>
      </plugin>
      <pose>0.805757 0.002002 0 0 -0 0</pose>
      <gazebo>
        <plugin filename='libROS2ConveyorBeltPlugin.so' name='ros2_conveyorbelt_plugin'>
          <ros>
            <namespace/>
          </ros>
          <max_velocity>0.2</max_velocity>
          <publish_rate>10</publish_rate>
        </plugin>
      </gazebo>
    </model>
    <model name='ur5_bin'>
      <link name='bottom'>
        <pose>0 0 0 0 -0 0</pose>
        <collision name='collision'>
          <geometry>
            <box>
              <size>0.4 0.4 0.02</size>
            </box>
          </geometry>
          <max_contacts>10</max_contacts>
          <surface>
            <contact>
              <ode/>
            </contact>
            <bounce/>
            <friction>
              <torsional>
                <ode/>
              </torsional>
              <ode/>
            </friction>
          </surface>
        </collision>
        <visual name='visual'>
          <geometry>
            <box>
              <size>0.4 0.4 0.02</size>
            </box>
          </geometry>
          <material>
            <script>
              <uri>file://media/materials/scripts/gazebo.material</uri>
              <name>Gazebo/Blue</name>
            </script>
          </material>
        </visual>
        <inertial>
          <mass>0.05</mass>
          <inertia>
            <ixx>0.001</ixx>
            <ixy>0</ixy>
            <ixz>0</ixz>
            <iyy>0.001</iyy>
            <iyz>0</iyz>
            <izz>0.001</izz>
          </inertia>
          <pose>0 0 0 0 -0 0</pose>
        </inertial>
        <self_collide>0</self_collide>
        <enable_wind>0</enable_wind>
        <kinematic>0</kinematic>
      </link>
      <link name='left'>
        <pose>-0.2 0 0.05 0 -0 0</pose>
        <collision name='collision'>
          <geometry>
            <box>
              <size>0.02 0.4 0.2</size>
            </box>
          </geometry>
          <max_contacts>10</max_contacts>
          <surface>
            <contact>
              <ode/>
            </contact>
            <bounce/>
            <friction>
              <torsional>
                <ode/>
              </torsional>
              <ode/>
            </friction>
          </surface>
        </collision>
        <visual name='visual'>
          <geometry>
            <box>
              <size>0.02 0.4 0.2</size>
            </box>
          </geometry>
          <material>
            <script>
              <uri>file://media/materials/scripts/gazebo.material</uri>
              <name>Gazebo/Blue</name>
            </script>
          </material>
        </visual>
        <inertial>
          <mass>0.05</mass>
          <inertia>
            <ixx>0.001</ixx>
            <ixy>0</ixy>
            <ixz>0</ixz>
            <iyy>0.001</iyy>
            <iyz>0</iyz>
            <izz>0.001</izz>
          </inertia>
          <pose>0 0 0 0 -0 0</pose>
        </inertial>
        <self_collide>0</self_collide>
        <enable_wind>0</enable_wind>
        <kinematic>0</kinematic>
      </link>
      <link name='right'>
        <pose>0.2 0 0.05 0 -0 0</pose>
        <collision name='collision'>
          <geometry>
            <box>
              <size>0.02 0.4 0.2</size>
            </box>
          </geometry>
          <max_contacts>10</max_contacts>
          <surface>
            <contact>
              <ode/>
            </contact>
            <bounce/>
            <friction>
              <torsional>
                <ode/>
              </torsional>
              <ode/>
            </friction>
          </surface>
        </collision>
        <visual name='visual'>
          <geometry>
            <box>
              <size>0.02 0.4 0.2</size>
            </box>
          </geometry>
          <material>
            <script>
              <uri>file://media/materials/scripts/gazebo.material</uri>
              <name>Gazebo/Blue</name>
            </script>
          </material>
        </visual>
        <inertial>
          <mass>0.05</mass>
          <inertia>
            <ixx>0.001</ixx>
            <ixy>0</ixy>
            <ixz>0</ixz>
            <iyy>0.001</iyy>
            <iyz>0</iyz>
            <izz>0.001</izz>
          </inertia>
          <pose>0 0 0 0 -0 0</pose>
        </inertial>
        <self_collide>0</self_collide>
        <enable_wind>0</enable_wind>
        <kinematic>0</kinematic>
      </link>
      <link name='back'>
        <pose>0 0.2 0.05 0 -0 0</pose>
        <collision name='collision'>
          <geometry>
            <box>
              <size>0.4 0.02 0.2</size>
            </box>
          </geometry>
          <max_contacts>10</max_contacts>
          <surface>
            <contact>
              <ode/>
            </contact>
            <bounce/>
            <friction>
              <torsional>
                <ode/>
              </torsional>
              <ode/>
            </friction>
          </surface>
        </collision>
        <visual name='visual'>
          <geometry>
            <box>
              <size>0.4 0.02 0.2</size>
            </box>
          </geometry>
          <material>
            <script>
              <uri>file://media/materials/scripts/gazebo.material</uri>
              <name>Gazebo/Blue</name>
            </script>
          </material>
        </visual>
        <inertial>
          <mass>0.05</mass>
          <inertia>
            <ixx>0.001</ixx>
            <ixy>0</ixy>
            <ixz>0</ixz>
            <iyy>0.001</iyy>
            <iyz>0</iyz>
            <izz>0.001</izz>
          </inertia>
          <pose>0 0 0 0 -0 0</pose>
        </inertial>
        <self_collide>0</self_collide>
        <enable_wind>0</enable_wind>
        <kinematic>0</kinematic>
      </link>
      <link name='front'>
        <pose>0 -0.2 0.05 0 -0 0</pose>
        <collision name='collision'>
          <geometry>
            <box>
              <size>0.4 0.02 0.2</size>
            </box>
          </geometry>
          <max_contacts>10</max_contacts>
          <surface>
            <contact>
              <ode/>
            </contact>
            <bounce/>
            <friction>
              <torsional>
                <ode/>
              </torsional>
              <ode/>
            </friction>
          </surface>
        </collision>
        <visual name='visual'>
          <geometry>
            <box>
              <size>0.4 0.02 0.2</size>
            </box>
          </geometry>
          <material>
            <script>
              <uri>file://media/materials/scripts/gazebo.material</uri>
              <name>Gazebo/Blue</name>
            </script>
          </material>
        </visual>
        <inertial>
          <mass>0.05</mass>
          <inertia>
            <ixx>0.001</ixx>
            <ixy>0</ixy>
            <ixz>0</ixz>
            <iyy>0.001</iyy>
            <iyz>0</iyz>
            <izz>0.001</izz>
          </inertia>
          <pose>0 0 0 0 -0 0</pose>
        </inertial>
        <self_collide>0</self_collide>
        <enable_wind>0</enable_wind>
        <kinematic>0</kinematic>
      </link>
      <joint name='left_wall' type='fixed'>
        <parent>bottom</parent>
        <child>left</child>
      </joint>
      <joint name='right_wall' type='fixed'>
        <parent>bottom</parent>
        <child>right</child>
      </joint>
      <joint name='back_wall' type='fixed'>
        <parent>bottom</parent>
        <child>back</child>
      </joint>
      <joint name='front_wall' type='fixed'>
        <parent>bottom</parent>
        <child>front</child>
      </joint>
      <pose>0.130137 -0.665022 0 0 -0 0</pose>
    </model>
    <model name='box2'>
      <link name='body'>
        <visual name='visual'>
          <pose>0 0 0.015 0 -0 0</pose>
          <geometry>
            <mesh>
              <uri>model://box2/box2.stl</uri>
              <scale>1 1 1</scale>
            </mesh>
          </geometry>
          <material>
            <script>
              <uri>model://box2/materials/scripts</uri>
              <uri>model://box2/materials/textures</uri>
              <name>box2color</name>
            </script>
            <shader type='vertex'>
              <normal_map>__default__</normal_map>
            </shader>
            <ambient>1 1 1 1</ambient>
            <diffuse>1 1 1 1</diffuse>
            <specular>0 0 0 1</specular>
            <emissive>0 0 0 1</emissive>
          </material>
        </visual>
        <collision name='collision_0'>
          <laser_retro>0</laser_retro>
          <max_contacts>10</max_contacts>
          <pose>-0.005 0 0 0 -0 0</pose>
          <geometry>
            <box>
              <size>0.42 0.21 0.005</size>
            </box>
          </geometry>
          <surface>
            <friction>
              <ode>
                <mu>1</mu>
                <mu2>1</mu2>
                <fdir1>0 0 0</fdir1>
                <slip1>0</slip1>
                <slip2>0</slip2>
              </ode>
              <torsional>
                <coefficient>1</coefficient>
                <patch_radius>0</patch_radius>
                <surface_radius>0</surface_radius>
                <use_patch_radius>1</use_patch_radius>
                <ode>
                  <slip>0</slip>
                </ode>
              </torsional>
            </friction>
            <bounce>
              <restitution_coefficient>0</restitution_coefficient>
              <threshold>1e+06</threshold>
            </bounce>
            <contact>
              <collide_without_contact>0</collide_without_contact>
              <collide_without_contact_bitmask>1</collide_without_contact_bitmask>
              <collide_bitmask>1</collide_bitmask>
              <ode>
                <soft_cfm>0</soft_cfm>
                <soft_erp>0.2</soft_erp>
                <kp>1e+13</kp>
                <kd>1</kd>
                <max_vel>0.01</max_vel>
                <min_depth>0</min_depth>
              </ode>
              <bullet>
                <split_impulse>1</split_impulse>
                <split_impulse_penetration_threshold>-0.01</split_impulse_penetration_threshold>
                <soft_cfm>0</soft_cfm>
                <soft_erp>0.2</soft_erp>
                <kp>1e+13</kp>
                <kd>1</kd>
              </bullet>
            </contact>
          </surface>
        </collision>
        <self_collide>0</self_collide>
        <enable_wind>0</enable_wind>
        <kinematic>0</kinematic>
      </link>
      <static>1</static>
      <pose>-0.405602 -0.456302 0 0 -0 0</pose>
    </model>
    <state world_name='default'>
      <sim_time>114 863000000</sim_time>
      <real_time>380 475310883</real_time>
      <wall_time>1729188087 455949396</wall_time>
      <iterations>114863</iterations>
      <model name='box2'>
        <pose>0.133697 -0.550459 0.21146 0 -0 0</pose>
        <scale>1 1 1</scale>
        <link name='body'>
          <pose>0.133697 -0.550459 0.21146 0 -0 0</pose>
          <velocity>0 0 0 0 -0 0</velocity>
          <acceleration>0 0 0 0 -0 0</acceleration>
          <wrench>0 0 0 0 -0 0</wrench>
        </link>
      </model>
      <model name='conveyor_belt'>
        <pose>0.805757 0.002002 -0.223086 0 -0 0</pose>
        <scale>1 1 1</scale>
        <model name='conveyorbelt_fixed'>
          <pose>0.805757 0.002002 -0.223086 0 -0 0</pose>
          <scale>1 1 1</scale>
          <link name='belt_visual'>
            <pose>0.805757 0.002002 -0.223086 0 -0 0</pose>
            <velocity>0 0 0 0 -0 0</velocity>
            <acceleration>0 0 0 0 -0 0</acceleration>
            <wrench>0 0 0 0 -0 0</wrench>
          </link>
        </model>
        <model name='conveyorbelt_moving'>
          <pose>0.805757 0.002002 0.517914 0 -0 0</pose>
          <scale>1 1 1</scale>
          <link name='belt_moving'>
            <pose>0.805757 0.002002 0.741 0 -0 0</pose>
            <velocity>0 0 0 0 -0 0</velocity>
            <acceleration>0 0 0 0 -0 0</acceleration>
            <wrench>0 0 0 0 -0 0</wrench>
          </link>
        </model>
      </model>
      <model name='ground_plane'>
        <pose>0 0 0 0 -0 0</pose>
        <scale>1 1 1</scale>
        <link name='link'>
          <pose>0 0 0 0 -0 0</pose>
          <velocity>0 0 0 0 -0 0</velocity>
          <acceleration>0 0 0 0 -0 0</acceleration>
          <wrench>0 0 0 0 -0 0</wrench>
        </link>
      </model>
      <model name='ur5'>
        <pose>1e-06 0 1e-06 1.9e-05 -1.2e-05 -2e-06</pose>
        <scale>1 1 1</scale>
        <link name='base_link'>
          <pose>1e-06 0 1e-06 1.9e-05 -1.2e-05 -2e-06</pose>
          <velocity>-9e-06 -1e-05 -1.3e-05 3.7e-05 -0.000577 5.7e-05</velocity>
          <acceleration>-0.014691 -0.010451 -0.012779 0.06412 -0.658127 0.05019</acceleration>
          <wrench>-0.058765 -0.041802 -0.051117 0 -0 0</wrench>
        </link>
        <link name='forearm_link'>
          <pose>0.054305 -1.7e-05 0.514953 -1.69694 1.56985 3.01576</pose>
          <velocity>3.1e-05 2e-06 -7e-06 0.0001 2.9e-05 0.000312</velocity>
          <acceleration>-0.014925 -0.043034 -0.003604 0.01074 -0.05439 1.59095</acceleration>
          <wrench>-0.033955 -0.097902 -0.0082 0 -0 0</wrench>
        </link>
        <link name='shoulder_link'>
          <pose>1.7e-05 -0 0.009989 -1.54929 1.57002 -3.11977</pose>
          <velocity>3e-05 2.2e-05 -1.9e-05 0.000114 -0.000254 0.000417</velocity>
          <acceleration>0.008224 0.018427 -0.012927 0.16541 -0.307654 0.398424</acceleration>
          <wrench>0.030427 0.06818 -0.047829 0 -0 0</wrench>
        </link>
        <link name='upper_arm_link'>
          <pose>0.053904 1.8e-05 0.089953 -1.65905 1.56986 3.05365</pose>
          <velocity>1.9e-05 3.9e-05 -9e-06 0.000112 1.2e-05 0.000341</velocity>
          <acceleration>0.001868 0.034025 0.00168 0.041482 -0.071563 1.12182</acceleration>
          <wrench>0.015679 0.28557 0.0141 0 -0 0</wrench>
        </link>
        <link name='wrist_1_link'>
          <pose>0.054676 -6.4e-05 0.907201 -1.68117 1.56985 3.03153</pose>
          <velocity>4.5e-05 -3.1e-05 -1.1e-05 9.5e-05 2.6e-05 0.000321</velocity>
          <acceleration>-0.023866 -0.040604 -0.003623 0.166642 -0.038881 0.313107</acceleration>
          <wrench>-0.029092 -0.049496 -0.004416 0 -0 0</wrench>
        </link>
        <link name='wrist_2_link'>
          <pose>0.110827 -4.6e-05 0.907148 -1.67936 1.56984 3.03333</pose>
          <velocity>5.1e-05 -8e-06 -1.2e-05 4.5e-05 7.9e-05 0.000314</velocity>
          <acceleration>-0.017838 -0.039241 -0.002684 0.099694 0.004888 0.335558</acceleration>
          <wrench>-0.021745 -0.047835 -0.003271 0 -0 0</wrench>
        </link>
        <link name='wrist_3_link'>
          <pose>0.152465 -4.4e-05 1.00203 -1.46089 -1.56984 -0.109607</pose>
          <velocity>5.9e-05 1e-06 -1.6e-05 4.5e-05 8.2e-05 0.00031</velocity>
          <acceleration>-0.017622 -0.020529 -0.002664 0.041924 0.000977 0.304807</acceleration>
          <wrench>-0.003318 -0.003866 -0.000502 0 -0 0</wrench>
        </link>
      </model>
      <model name='ur5_bin'>
        <pose>0.130171 -0.664876 0.05 0 0 -1.7e-05</pose>
        <scale>1 1 1</scale>
        <link name='back'>
          <pose>0.130174 -0.464876 0.1 -0 -0 -1.7e-05</pose>
          <velocity>0 0 -0 0 1e-06 0</velocity>
          <acceleration>7.3e-05 9.9e-05 -0.00011 -0.000432 0.000725 0.000276</acceleration>
          <wrench>4e-06 5e-06 -6e-06 0 -0 0</wrench>
        </link>
        <link name='bottom'>
          <pose>0.130171 -0.664876 0.05 0 0 -1.7e-05</pose>
          <velocity>0 0 -0 0 -0 0</velocity>
          <acceleration>0.000153 6.7e-05 -2.7e-05 -5.6e-05 2.7e-05 1.8e-05</acceleration>
          <wrench>8e-06 3e-06 -1e-06 0 -0 0</wrench>
        </link>
        <link name='front'>
          <pose>0.130167 -0.864876 0.1 0 0 -1.7e-05</pose>
          <velocity>0 0 0 -1e-06 -0 -1e-06</velocity>
          <acceleration>4.7e-05 8.9e-05 2e-05 -0.000242 0.000425 -0.000316</acceleration>
          <wrench>2e-06 4e-06 1e-06 0 -0 0</wrench>
        </link>
        <link name='left'>
          <pose>-0.069829 -0.664872 0.1 0 0 -1.7e-05</pose>
          <velocity>0 0 -0 0 0 -1e-06</velocity>
          <acceleration>0.000152 2.5e-05 -3.5e-05 -0.000234 0.000242 -0.000637</acceleration>
          <wrench>8e-06 1e-06 -2e-06 0 -0 0</wrench>
        </link>
        <link name='right'>
          <pose>0.330171 -0.664879 0.1 0 0 -1.7e-05</pose>
          <velocity>0 0 -0 0 -0 0</velocity>
          <acceleration>0.000129 3.3e-05 2e-06 -0.000357 0.000466 0.000407</acceleration>
          <wrench>6e-06 2e-06 0 0 -0 0</wrench>
        </link>
      </model>
      <light name='sun'>
        <pose>0 0 10 0 -0 0</pose>
      </light>
    </state>
    <gui fullscreen='0'>
      <camera name='user_camera'>
        <pose>-2.59588 -4.86314 2.1976 0 0.339643 0.900195</pose>
        <view_controller>orbit</view_controller>
        <projection_type>perspective</projection_type>
      </camera>
    </gui>
  </world>
</sdf>
